Workbook

Sheet AZIR website
H2: AZIR indeksi ilə bağlı məlumatlar
H3: Yenilənmə tarixi | I3: =MAX(B24:B10365) -> 45923
H4: Faiz indeksi, %-lə | I4: =INDEX(C24:C10365,MATCH(I3,B24:B10365)) -> 0.06943
H5: Ötən ayın sonundan faiz fərqi | I5: =I4-INDEX(C24:C10365,MATCH(_xlfn.MAXIFS(B24:B10365,B24:B10365,"<="&EOMONTH(I3,-1),B24:B10365,">="&EOMONTH(I3,-2)),B24:B10365)) -> -0.000466
H6: Ötən ilin sonundan faiz fərqi | I6: =IFERROR(I4-INDEX(C24:C10365,MATCH(_xlfn.MAXIFS(B24:B10365,B24:B10365,"<="&DATE(YEAR(I3)-1,12,31),B24:B10365,">="&DATE(YEAR(I3)-1,1,1)),B24:B10365)),"-") -> 0.00393
H7: Son 1 ildə minimum faiz | I7: =_xlfn.MINIFS(C24:C10365,B24:B10365,"<="&I3,B24:B10365,">"&DATE(YEAR(I3)-1,MONTH(I3),DAY(I3))) -> 0.0633
H8: Son 1 ildə maksimum faiz | I8: =_xlfn.MAXIFS(C24:C10365,B24:B10365,"<="&I3,B24:B10365,">"&DATE(YEAR(I3)-1,MONTH(I3),DAY(I3))) -> 0.0791
H9: Əməliyyat həcmi, mln. manatla | I9: =INDEX(D24:D10365,MATCH(I3,B24:B10365)) -> 252
H10: Ötən ayın sonundan dəyişim | I10: =I9-INDEX(D24:D10365,MATCH(_xlfn.MAXIFS(B24:B10365,B24:B10365,"<="&EOMONTH(I3,-1),B24:B10365,">="&EOMONTH(I3,-2)),B24:B10365)) -> 82
H11: Son 1 ildə minimum həcm | I11: =_xlfn.MINIFS(D24:D10365,B24:B10365,"<="&I3,B24:B10365,">"&DATE(YEAR(I3)-1,MONTH(I3),DAY(I3))) -> 43.4
H12: Son 1 ildə maksimum həcm | I12: =_xlfn.MAXIFS(D24:D10365,B24:B10365,"<="&I3,B24:B10365,">"&DATE(YEAR(I3)-1,MONTH(I3),DAY(I3))) -> 988.9
H13: Əməliyyat həcminin dollarla ifadəsi, mln. USD | I13: =I9/1.7 -> 148.23529
B18: *Banklararası Təminatsız Pul Bazarında İstinad Faiz Dərəcəsi - AZIR (Azerbaijan Interbank Rate)
B21: AZIR indeksi ilə bağlı məlumatlar
B23: Tarix | C23: Faiz | D23: Əqdlərin həcmi, mln. ₼ | E23: Əqdlərin sayı
B24: 45047 | C24: 0.049692825 | D24: 111.5 | E24: 11
B25: 45048 | C25: 0.0494 | D25: 161 | E25: 16
B26: 45049 | C26: 0.0493 | D26: 162 | E26: 14
B27: 45050 | C27: 0.0535 | D27: 147 | E27: 14
B28: 45051 | C28: 0.0538 | D28: 142.5 | E28: 14
B29: 45054 | C29: 0.0535 | D29: 155 | E29: 15
B30: 45056 | C30: 0.0535 | D30: 149.5 | E30: 14
B31: 45057 | C31: 0.0537 | D31: 179 | E31: 17
B32: 45058 | C32: 0.0534 | D32: 168 | E32: 14
B33: 45061 | C33: 0.0538 | D33: 157 | E33: 13
B34: 45062 | C34: 0.0539 | D34: 174 | E34: 14
B35: 45063 | C35: 0.054 | D35: 161 | E35: 15
... B41: 45071 | C41: 0.0546 | D41: 267.3 | E41: 22
B42: 45072 | C42: 0.0546
B43: 45076 | C43: 0.0544 | D43: 263.8 | E43: 21
B44: 45077 | C44: 0.0546 | D44: 215 | E44: 18
B45: 45078 | C45: 0.054 | D45: 188 | E45: 16
B46: 45079 | C46: 0.0545 | D46: 181.5 | E46: 16
B47: 45082 | C47: 0.0548 | D47: 202.5 | E47: 18
B48: 45083 | C48: 0.0553 | D48: 198.5 | E48: 18
B49: 45084 | C49: 0.0545 | D49: 201.5 | E49: 16
B50: 45085 | C50: 0.0558 | D50: 162 | E50: 15
B51: 45086 | C51: 0.0556 | D51: 157.5 | E51: 14
B52: 45089 | C52: 0.0557 | D52: 158.5 | E52: 15
B53: 45090 | C53: 0.0565 | D53: 140 | E53: 12
...

Sheet 1D AZIR və 1W AZIR
B2: Tarix | C2: 1D AZIR | F2: 1W AZIR
C3: Faiz indeksi | D3: İndeksi formalaşdıran əməliyyatların həcmi, mln. ₼ | E3: İndeksi formalaşdıran əməliyyatların sayı | F3: Faiz indeksi | G3: İndeksi formalaşdıran əməliyyatların həcmi, mln. ₼ | H3: İndeksi formalaşdıran əməliyyatların sayı
B4: 45047 | C4: 0.049692825 | D4: 111.5 | E4: 11
B5: 45048 | C5: 0.0494 | D5: 161 | E5: 16 | F5: 0.0549 | G5: 36 | H5: 2
B6: 45049 | C6: 0.0493 | D6: 162 | E6: 14 | F6: 0.0549
B7: 45050 | C7: 0.0535 | D7: 147 | E7: 14 | F7: 0.0575 | G7: 10 | H7: 1
B8: 45051 | C8: 0.0538 | D8: 142.5 | E8: 14 | F8: 0.0575 | G8: 16 | H8: 1
B9: 45054 | C9: 0.0535 | D9: 155 | E9: 15 | F9: 0.0575
B10: 45056 | C10: 0.0535 | D10: 149.5 | E10: 14 | F10: 0.0593 | G10: 46 | H10: 3
B11: 45057 | C11: 0.0537 | D11: 179 | E11: 17 | F11: 0.0593
B12: 45058 | C12: 0.0534 | D12: 168 | E12: 14 | F12: 0.0575 | G12: 16 | H12: 1
B13: 45061 | C13: 0.0538 | D13: 157 | E13: 13 | F13: 0.0575
B14: 45062 | C14: 0.0539 | D14: 174 | E14: 14 | F14: 0.0575
B15: 45063 | C15: 0.054 | D15: 161 | E15: 15 | F15: 0.0593 | G15: 46 | H15: 3
B16: 45064 | C16: 0.054 | D16: 184 | E16: 16 | F16: 0.0593
B17: 45065 | C17: 0.0536 | D17: 160 | E17: 16 | F17: 0.0593
B18: 45068 | C18: 0.0532 | D18: 126 | E18: 12 | F18: 0.0593
B19: 45069 | C19: 0.0538 | D19: 179.8 | E19: 14 | F19: 0.0593
B20: 45070 | C20: 0.055 | D20: 235.3 | E20: 19 | F20: 0.0575 | G20: 10 | H20: 1
B21: 45071 | C21: 0.0546 | D21: 267.3 | E21: 22 | F21: 0.0575
B22: 45072 | C22: 0.0546 | F22: 0.0575
B23: 45076 | C23: 0.0544 | D23: 263.8 | E23: 21 | F23: 0.0575
B24: 45077 | C24: 0.0546 | D24: 215 | E24: 18 | F24: 0.0575 | G24: 10 | H24: 1
B25: 45078 | C25: 0.054 | D25: 188 | E25: 16 | F25: 0.0575
B26: 45079 | C26: 0.0545 | D26: 181.5 | E26: 16 | F26: 0.0575
B27: 45082 | C27: 0.0548 | D27: 202.5 | E27: 18
B28: 45083 | C28: 0.0553 | D28: 198.5 | E28: 18
B29: 45084 | C29: 0.0545 | D29: 201.5 | E29: 16 | F29: 0.0575 | G29: 10 | H29: 1
B30: 45085 | C30: 0.0558 | D30: 162 | E30: 15 | F30: 0.0575
B31: 45086 | C31: 0.0556 | D31: 157.5 | E31: 14 | F31: 0.0575
B32: 45089 | C32: 0.0557 | D32: 158.5 | E32: 15 | F32: 0.0575
B33: 45090 | C33: 0.0565 | D33: 140 | E33: 12 | F33: 0.0575
B34: 45091 | C34: 0.0558 | D34: 164 | E34: 14 | F34: 0.0575 | G34: 10 | H34: 1
B35: 45093 | C35: 0.0558 | D35: 180 | E35: 16 | F35: 0.0575
B36: 45096 | C36: 0.0564 | D36: 135 | E36: 11 | F36: 0.0575
B37: 45097 | C37: 0.0564 | D37: 159.5 | E37: 12 | F37: 0.0575
B38: 45098 | C38: 0.0565 | D38: 169.5 | E38: 13 | F38: 0.0575
B39: 45099 | C39: 0.0563 | D39: 183 | E39: 16 | F39: 0.0575
B40: 45100 | C40: 0.0564 | D40: 173 | E40: 14 | F40: 0.0575
B41: 45101 | C41: 0.0563 | D41: 176.5 | E41: 14
...

Sheet 1D AZIR və 1W AZIR %
B2: Tarix | C2: 1D AZIR | D2: 1W AZIR
B3: 45047 | C3: 0.049692825
B4: 45048 | C4: 0.0494 | D4: 0.0549
B5: 45049 | C5: 0.0493 | D5: 0.0549
B6: 45050 | C6: 0.0535 | D6: 0.0575
B7: 45051 | C7: 0.0538 | D7: 0.0575
B8: 45054 | C8: 0.0535 | D8: 0.0575
B9: 45056 | C9: 0.0535 | D9: 0.0593
B10: 45057 | C10: 0.0537 | D10: 0.0593
B11: 45058 | C11: 0.0534 | D11: 0.0575
B12: 45061 | C12: 0.0538 | D12: 0.0575
B13: 45062 | C13: 0.0539 | D13: 0.0575
B14: 45063 | C14: 0.054 | D14: 0.0593
B15: 45064 | C15: 0.054 | D15: 0.0593
... B25: 45079 | C25: 0.0545 | D25: 0.0575
B26: 45082 | C26: 0.0548
B27: 45083 | C27: 0.0553
B28: 45084 | C28: 0.0545 | D28: 0.0575
B29: 45085 | C29: 0.0558 | D29: 0.0575
B30: 45086 | C30: 0.0556 | D30: 0.0575
B31: 45089 | C31: 0.0557 | D31: 0.0575
B32: 45090 | C32: 0.0565 | D32: 0.0575
B33: 45091 | C33: 0.0558 | D33: 0.0575
B34: 45093 | C34: 0.0558 | D34: 0.0575
B35: 45096 | C35: 0.0564 | D35: 0.0575
B36: 45097 | C36: 0.0564 | D36: 0.0575
B37: 45098 | C37: 0.0565 | D37: 0.0575
B38: 45099 | C38: 0.0563 | D38: 0.0575
B39: 45100 | C39: 0.0564 | D39: 0.0575
B40: 45101 | C40: 0.0563
B41: 45102 | C41: 0.0563 | D41: 0.0517
B42: 45110 | C42: 0.0567 | D42: 0.0575
B43: 45111 | C43: 0.0564 | D43: 0.0575
B44: 45112 | C44: 0.056 | D44: 0.0575
B45: 45113 | C45: 0.0567 | D45: 0.0575
B46: 45114 | C46: 0.0563 | D46: 0.0575
B47: 45117 | C47: 0.0558 | D47: 0.0575
B48: 45118 | C48: 0.0563 | D48: 0.0575
B49: 45119 | C49: 0.0567 | D49: 0.0575
B50: 45120 | C50: 0.0564 | D50: 0.0575
...

Sheet 1D AZIR və 1W AZIR   VOLUME
B2: Tarix | C2: 1D AZIR | D2: 1W AZIR
B3: 45047 | C3: 111.5
B4: 45048 | C4: 161 | D4: 36
B5: 45049 | C5: 162
B6: 45050 | C6: 147 | D6: 10
B7: 45051 | C7: 142.5 | D7: 16
B8: 45054 | C8: 155
B9: 45056 | C9: 149.5 | D9: 46
B10: 45057 | C10: 179
B11: 45058 | C11: 168 | D11: 16
B12: 45061 | C12: 157
B13: 45062 | C13: 174
B14: 45063 | C14: 161 | D14: 46
B15: 45064 | C15: 184
B16: 45065 | C16: 160
B17: 45068 | C17: 126
B18: 45069 | C18: 179.8
B19: 45070 | C19: 235.3 | D19: 10
B20: 45071 | C20: 267.3
B21: 45072
B22: 45076 | C22: 263.8
B23: 45077 | C23: 215 | D23: 10
B24: 45078 | C24: 188
B25: 45079 | C25: 181.5
B26: 45082 | C26: 202.5
B27: 45083 | C27: 198.5
B28: 45084 | C28: 201.5 | D28: 10
B29: 45085 | C29: 162
B30: 45086 | C30: 157.5
B31: 45089 | C31: 158.5
B32: 45090 | C32: 140
B33: 45091 | C33: 164 | D33: 10
B34: 45093 | C34: 180
B35: 45096 | C35: 135
B36: 45097 | C36: 159.5
B37: 45098 | C37: 169.5
B38: 45099 | C38: 183
B39: 45100 | C39: 173
B40: 45101 | C40: 176.5
B41: 45102 | D41: 47
...

Sheet 1D AZIR və 1W AZIR   COUNT
B2: Tarix | C2: 1D AZIR | D2: 1W AZIR
B3: 45047 | C3: 11
B4: 45048 | C4: 16 | D4: 2
B5: 45049 | C5: 14
B6: 45050 | C6: 14 | D6: 1
B7: 45051 | C7: 14 | D7: 1
B8: 45054 | C8: 15
B9: 45056 | C9: 14 | D9: 3
B10: 45057 | C10: 17
B11: 45058 | C11: 14 | D11: 1
B12: 45061 | C12: 13
B13: 45062 | C13: 14
B14: 45063 | C14: 15 | D14: 3
B15: 45064 | C15: 16
B16: 45065 | C16: 16
B17: 45068 | C17: 12
B18: 45069 | C18: 14
B19: 45070 | C19: 19 | D19: 1
B20: 45071 | C20: 22
B21: 45072
B22: 45076 | C22: 21
B23: 45077 | C23: 18 | D23: 1
B24: 45078 | C24: 16
B25: 45079 | C25: 16
B26: 45082 | C26: 18
B27: 45083 | C27: 18
B28: 45084 | C28: 16 | D28: 1
B29: 45085 | C29: 15
B30: 45086 | C30: 14
B31: 45089 | C31: 15
B32: 45090 | C32: 12
B33: 45091 | C33: 14 | D33: 1
B34: 45093 | C34: 16
B35: 45096 | C35: 11
B36: 45097 | C36: 12
B37: 45098 | C37: 13
B38: 45099 | C38: 16
B39: 45100 | C39: 14
B40: 45101 | C40: 14
B41: 45102 | D41: 6
...

Sheet Toplanan Faizli indekslər
B2: Toplanan faizli 30, 90, 180 günlük AZIR* | H2: Toplanan Faizli Artan AZIR indeksi (TFAİ)** (01.11.2024=100)
B5: *Toplanan faizli 30,90, 180 günlük AZİR hesablanma qaydası ilə metodologiya sənədində tanış ola bilərsiniz. | H5: **Toplanan Faizli Artan AZİR hesablanma qaydası ilə metodologiya sənədində tanış ola bilərsiniz.
B6: Tarix | C6: Toplanan faizli 30 günlük AZIR | D6: Toplanan faizli 90 günlük AZIR | E6: Toplanan faizli 180 günlük AZIR | H6: Tarix | I6: TFAİ*
B7: ='AZIR website'!B603 -> 45923 | C7: 0.069884 | D7: 0.070994 | E7: 0.071545 | H7: 45597 | I7: 100
H8: 45600 | I8: 100.02089
H9: 45601 | I9: 100.04173
H10: 45602 | I10: 100.06257
H11: 45603 | I11: 100.08342
H12: 45604 | I12: 100.10427
H13: 45607 | I13: 100.16683
H14: 45608 | I14: 100.1877
H15: 45609 | I15: 100.20857
H16: 45610 | I16: 100.23
H17: 45611 | I17: 100.25128
H18: 45614 | I18: 100.31513
H19: 45615 | I19: 100.33661
... H233: 45923 | I233: 106.63895
